Workbook

Sheet 表紙
K5: 株式会社○○御中
G17: =更新履歴!$G$3 -> ○○○○検証
G33: テスト設計書 ほにゃらら
M50: ="第"&(MAX(更新履歴!$G$7:$L$65))&"版" -> 第1.1版
M52: =MAX(更新履歴!$A$7:$F$65) -> 43115
M54: ="作成"&" "&更新履歴!AC2 -> 作成 SHIFT 佐藤

Sheet 更新履歴
A1: 帳票タイトル | B1: 0 | E1: 0 | F1: 0 | G1: テスト設計書 | H1: 0 | I1: 0 | J1: 0 | K1: 0 | L1: 0 | M1: 0 | N1: 0 | O1: 0 | P1: 0 | Q1: 管理番号 | R1: 0 | S1: 0 | T1: 0 | U1: ○○-0001 | Y1: 作成日 | Z1: 0 | AA1: 0 | AB1: 0 | AC1: =MIN(A7:F65) -> 41757 | AG1: 最終更新日 | AH1: 0 | AI1: 0 | AJ1: 0 | AK1: =MAX(A7:F65) -> 43115
A2: 0 | B2: 0 | E2: 0 | F2: 0 | G2: 0 | H2: 0 | I2: 0 | J2: 0 | K2: 0 | L2: 0 | M2: 0 | N2: 0 | O2: 0 | P2: 0 | Q2: バージョン | R2: 0 | S2: 0 | T2: 0 | U2: 1 | Y2: 作成者 | Z2: 0 | AA2: 0 | AB2: 0 | AC2: =VLOOKUP(AC1,A7:R50,13,FALSE) -> SHIFT 佐藤 | AG2: 更新者 | AH2: 0 | AI2: 0 | AJ2: 0 | AK2: =VLOOKUP(AK1,A7:R50,13,FALSE) -> SHIFT 佐藤
A3: プロジェクト名 | B3: 0 | C3: 0 | D3: 0 | E3: 0 | F3: 0 | G3: ○○○○検証
A4: プロダクト名 | B4: 0 | C4: 0 | D4: 0 | E4: 0 | F4: 0 | G4: ○○○○ | U4: サブ名 | V4: 0 | W4: 0 | X4: 0 | Y4: 0 | Z4: 0 | AA4: ○○○○
A6: 更新日 | G6: バージョン | M6: 更新者 | S6: 更新内容
A7: 41757 | G7: 1 | M7: SHIFT 佐藤 | S7: 初期バージョン作成
A8: 43115 | G8: 1.1 | M8: SHIFT 佐藤 | S8: ○○を修正

Sheet 集計
A1: 帳票タイトル | B1: 0 | E1: 0 | F1: 0 | G1: =更新履歴!G1 -> テスト設計書 | H1: 0 | I1: 0 | J1: 0 | K1: 0 | L1: 0 | M1: 0 | N1: 0 | O1: 0 | P1: 0 | Q1: 管理番号 | R1: 0 | S1: 0 | T1: 0 | U1: =更新履歴!U1 -> ○○-0001 | Y1: 作成日 | Z1: 0 | AA1: 0 | AB1: 0 | AC1: =更新履歴!AC1 -> 41757 | AG1: 最終更新日 | AH1: 0 | AI1: 0 | AJ1: 0 | AK1: =更新履歴!AK1 -> 43115
A2: 0 | B2: 0 | E2: 0 | F2: 0 | G2: 0 | H2: 0 | I2: 0 | J2: 0 | K2: 0 | L2: 0 | M2: 0 | N2: 0 | O2: 0 | P2: 0 | Q2: バージョン | R2: 0 | S2: 0 | T2: 0 | U2: =更新履歴!U2 -> 1 | Y2: 作成者 | Z2: 0 | AA2: 0 | AB2: 0 | AC2: =更新履歴!AC2 -> SHIFT 佐藤 | AG2: 更新者 | AH2: 0 | AI2: 0 | AJ2: 0 | AK2: =更新履歴!AK2 -> SHIFT 佐藤
A3: プロジェクト名 | B3: 0 | C3: 0 | D3: 0 | E3: 0 | F3: 0 | G3: =更新履歴!G3 -> ○○○○検証
A4: プロダクト名 | B4: 0 | C4: 0 | D4: 0 | E4: 0 | F4: 0 | G4: =更新履歴!G4 -> ○○○○ | U4: サブ名 | V4: 0 | W4: 0 | X4: 0 | Y4: 0 | Z4: 0 | AA4: =更新履歴!AA4 -> ○○○○
B6: 1 | C6: ファイル構成
C8: # | D8: シート名 | P8: 概要
C9: 1 | D9: 確認項目一覧 | P9: 仕様書より抽出した機能及びそれを確認するための項目一覧表
B13: 2 | C13: テスト設計ボリューム結果
C15: ■テスト設計範囲 | W15: ■実行対象範囲
C16: 項目名 | H16: 件数 | W16: 項目名 | AB16: 件数
C17: 対象確認項目数 | H17: =COUNTA(確認項目一覧!$B:$B)-2 -> 43 | W17: 対象確認項目数 | AB17: =COUNTA(確認項目一覧!$B:$B)-2 -> 43
C18: 設計パターン数 | H18: 0 | W18: 設計パターン数 | AB18: 0
C19: テストケース数 | H19: =COUNTIF(確認項目一覧!$H:$H,"-")+H18 -> 43 | W19: テストケース数 | AB19: =COUNTIF(確認項目一覧!$H:$H,"-")+AB18 -> 43
C21: 総テスト数 | H21: =H19 -> 43 | W21: 実施予定テスト数 | AB21: =AB19 -> 43

Sheet 確認項目一覧
B4: No | C4: テスト区分 | D4: 【画面】：画面名 【機能】：業務機能名 | E4: 【画面】：画面エリア 【機能】：業務機能詳細項目 | F4: 【画面】：テスト対象要素項目 【機能】：テスト対象機能項目 | G4: 手順 | H4: PTN | I4: テスト観点 | J4: 確認項目 | K4: 期待値 | L4: 設計備考 | M4: 実行結果 | N4: 課題No. | O4: 備考
B5: =ROW()-ROW($B$4) -> 1 | C5: 設計積算機能 | D5: 基準予算（鑑）画面 | E5: 基準入力エリア | F5: アイテム区分リストボックス | G5: - | H5: - | I5: リストアイテム | J5: リストのアイテムが期待値通りであること、文字切れしていないこと | K5: プルダウンのリストに 未選択 全体 部分 と表示されていること | L5: - | M5: OK | O5: (以下同)テストは「00001 しふと たろう」でのみ実施につき、 今回の実行結果の判定には、ほかの権限や状態は考慮されていません。
B6: =ROW()-ROW($B$4) -> 2 | C6: =INDIRECT(ADDRESS(ROW()-1,COLUMN())) -> 設計積算機能 | D6: =INDIRECT(ADDRESS(ROW()-1,COLUMN())) -> 基準予算（鑑）画面 | E6: =INDIRECT(ADDRESS(ROW()-1,COLUMN())) -> 基準入力エリア | F6: =INDIRECT(ADDRESS(ROW()-1,COLUMN())) -> アイテム区分リストボックス | G6: - | H6: - | I6: 初期制御 | J6: 画面を開いた直後の画面で、表示/非表示や活性/非活性が期待値通りであること（権限や状態などによる分岐も確認以下同） | K6: 初期表示は「未選択」であること | L6: - | M6: OK | O6: 初期化 押下時に 未選択 であることを確認。
B7: =ROW()-ROW($B$4) -> 3 | C7: =INDIRECT(ADDRESS(ROW()-1,COLUMN())) -> 設計積算機能 | D7: =INDIRECT(ADDRESS(ROW()-1,COLUMN())) -> 基準予算（鑑）画面 | E7: =INDIRECT(ADDRESS(ROW()-1,COLUMN())) -> 基準入力エリア | F7: 版数テキストボックス | G7: - | H7: - | I7: 初期制御 | J7: 画面を開いた直後の画面で、表示/非表示や活性/非活性が期待値通りであること（権限や状態などによる分岐も確認以下同） | K7: 初期表示は空欄であること | L7: - | M7: OK | O7: 初期化 押下時に 空欄 であることを確認。
B8: =ROW()-ROW($B$4) -> 4 | C8: =INDIRECT(ADDRESS(ROW()-1,COLUMN())) -> 設計積算機能 | D8: =INDIRECT(ADDRESS(ROW()-1,COLUMN())) -> 基準予算（鑑）画面 | E8: =INDIRECT(ADDRESS(ROW()-1,COLUMN())) -> 基準入力エリア | F8: 設計担当部署コード テキストボックス | G8: - | H8: - | I8: 初期制御 | J8: 画面を開いた直後の画面で、表示/非表示や活性/非活性が期待値通りであること（権限や状態などによる分岐も確認以下同） | K8: 初期表示は、 0070 と表示されていること | L8: - | M8: OK | O8: 初期化 押下時に 0070 であることを確認。
B9: =ROW()-ROW($B$4) -> 5 | C9: =INDIRECT(ADDRESS(ROW()-1,COLUMN())) -> 設計積算機能 | D9: =INDIRECT(ADDRESS(ROW()-1,COLUMN())) -> 基準予算（鑑）画面 | E9: =INDIRECT(ADDRESS(ROW()-1,COLUMN())) -> 基準入力エリア | F9: 設計担当部署コード ラベル | G9: - | H9: - | I9: 初期制御 | J9: 画面を開いた直後の画面で、表示/非表示や活性/非活性が期待値通りであること（権限や状態などによる分岐も確認以下同） | K9: 初期表示は、 設計G と表示されていること | L9: - | M9: OK | O9: 初期化 押下時に 設計G であることを確認。
B10: =ROW()-ROW($B$4) -> 6 | C10: =INDIRECT(ADDRESS(ROW()-1,COLUMN())) -> 設計積算機能 | D10: =INDIRECT(ADDRESS(ROW()-1,COLUMN())) -> 基準予算（鑑）画面 | E10: =INDIRECT(ADDRESS(ROW()-1,COLUMN())) -> 基準入力エリア | F10: 設計担当者コード テキストボックス | G10: - | H10: - | I10: 初期制御 | J10: 画面を開いた直後の画面で、表示/非表示や活性/非活性が期待値通りであること（権限や状態などによる分岐も確認以下同） | K10: 初期表示は、 00003 と表示されていること | L10: - | M10: OK | O10: 初期化 押下時に 00003 であることを確認。
B11: =ROW()-ROW($B$4) -> 7 | C11: =INDIRECT(ADDRESS(ROW()-1,COLUMN())) -> 設計積算機能 | D11: =INDIRECT(ADDRESS(ROW()-1,COLUMN())) -> 基準予算（鑑）画面 | E11: =INDIRECT(ADDRESS(ROW()-1,COLUMN())) -> 基準入力エリア | F11: 設計担当者コード ラベル | G11: - | H11: - | I11: 初期制御 | J11: 画面を開いた直後の画面で、表示/非表示や活性/非活性が期待値通りであること（権限や状態などによる分岐も確認以下同） | K11: 初期表示は、 とうきょう たろう と表示されていること | L11: - | M11: NG | N11: 1 | O11: ・OK：初期化 押下時に とうきょう たろう であることを確認。 ・NG:DATAにない値を入力した場合、 見つかりません が表示されない
B12: =ROW()-ROW($B$4) -> 8 | C12: =INDIRECT(ADDRESS(ROW()-1,COLUMN())) -> 設計積算機能 | D12: =INDIRECT(ADDRESS(ROW()-1,COLUMN())) -> 基準予算（鑑）画面 | E12: =INDIRECT(ADDRESS(ROW()-1,COLUMN())) -> 基準入力エリア | F12: 積算担当部署コード テキストボックス | G12: - | H12: - | I12: 初期制御 | J12: 画面を開いた直後の画面で、表示/非表示や活性/非活性が期待値通りであること（権限や状態などによる分岐も確認以下同） | K12: 初期表示は、 0080 と表示されていること | L12: - | M12: OK | O12: 初期化 押下時に 0080 であることを確認。
B13: =ROW()-ROW($B$4) -> 9 | C13: =INDIRECT(ADDRESS(ROW()-1,COLUMN())) -> 設計積算機能 | D13: =INDIRECT(ADDRESS(ROW()-1,COLUMN())) -> 基準予算（鑑）画面 | E13: =INDIRECT(ADDRESS(ROW()-1,COLUMN())) -> 基準入力エリア | F13: 積算担当部署コード ラベル | G13: - | H13: - | I13: 初期制御 | J13: 画面を開いた直後の画面で、表示/非表示や活性/非活性が期待値通りであること（権限や状態などによる分岐も確認以下同） | K13: 初期表示は、 積算G と表示されていること | L13: - | M13: OK | O13: 初期化 押下時に 積算G であることを確認。
B14: =ROW()-ROW($B$4) -> 10 | C14: =INDIRECT(ADDRESS(ROW()-1,COLUMN())) -> 設計積算機能 | D14: =INDIRECT(ADDRESS(ROW()-1,COLUMN())) -> 基準予算（鑑）画面 | E14: =INDIRECT(ADDRESS(ROW()-1,COLUMN())) -> 基準入力エリア | F14: 積算担当者コード テキストボックス | G14: - | H14: - | I14: 初期制御 | J14: 画面を開いた直後の画面で、表示/非表示や活性/非活性が期待値通りであること（権限や状態などによる分岐も確認以下同） | K14: 初期表示は、 0006 と表示されていること | L14: - | M14: OK | O14: 初期化 押下時に 00006 であることを確認。
B15: =ROW()-ROW($B$4) -> 11 | C15: =INDIRECT(ADDRESS(ROW()-1,COLUMN())) -> 設計積算機能 | D15: =INDIRECT(ADDRESS(ROW()-1,COLUMN())) -> 基準予算（鑑）画面 | E15: =INDIRECT(ADDRESS(ROW()-1,COLUMN())) -> 基準入力エリア | F15: 積算担当者コード ラベル | G15: - | H15: - | I15: 初期制御 | J15: 画面を開いた直後の画面で、表示/非表示や活性/非活性が期待値通りであること（権限や状態などによる分岐も確認以下同） | K15: 初期表示は、 さっぽろ はなこ と表示されていること | L15: - | M15: OK | O15: 初期化 押下時に さっぽろ はなこ であることを確認。
B16: =ROW()-ROW($B$4) -> 12 | C16: =INDIRECT(ADDRESS(ROW()-1,COLUMN())) -> 設計積算機能 | D16: =INDIRECT(ADDRESS(ROW()-1,COLUMN())) -> 基準予算（鑑）画面 | E16: 予算一覧エリア | F16: A 工番金額(税抜) | G16: - | H16: - | I16: 書式（色） | J16: 期待値通りであること（色、フォント、フォントサイズ、文字の寄せ方向、マージン、境界線の太さなど） | K16: 数値が黒色であること （マイナス値の場合のみ赤色であること） | L16: - | M16: 保留 | N16: 2 | O16: 0以上の値：OK マイナスの値：未確認
B17: =ROW()-ROW($B$4) -> 13 | C17: =INDIRECT(ADDRESS(ROW()-1,COLUMN())) -> 設計積算機能 | D17: =INDIRECT(ADDRESS(ROW()-1,COLUMN())) -> 基準予算（鑑）画面 | E17: =INDIRECT(ADDRESS(ROW()-1,COLUMN())) -> 予算一覧エリア | F17: =INDIRECT(ADDRESS(ROW()-1,COLUMN())) -> A 工番金額(税抜) | G17: - | H17: - | I17: 書式（形式） | J17: 期待値通りであること（色、フォント、フォントサイズ、文字の寄せ方向、マージン、境界線の太さなど） | K17: 金額は、3桁ずつのカンマ区切り 比率は、小数点以下1桁まで表示されていること | L17: - | M17: NG | N17: 3,4 | O17: ・金額NG：カンマがない -> 工番伝票 最新版数 ・比率NG：小数点以下表示がない -> 基準予算1版、工番伝票 最新版数、基準予算 最新版数
B18: =ROW()-ROW($B$4) -> 14 | C18: =INDIRECT(ADDRESS(ROW()-1,COLUMN())) -> 設計積算機能 | D18: =INDIRECT(ADDRESS(ROW()-1,COLUMN())) -> 基準予算（鑑）画面 | E18: =INDIRECT(ADDRESS(ROW()-1,COLUMN())) -> 予算一覧エリア | F18: 機器・工事費 | G18: - | H18: - | I18: 書式（色） | J18: 期待値通りであること（色、フォント、フォントサイズ、文字の寄せ方向、マージン、境界線の太さなど） | K18: 数値が黒色であること （マイナス値の場合のみ赤色であること） | L18: - | M18: OK | O18: 0以上の値：黒色であることを確認 マイナスの値：赤字であることを確認
B19: =ROW()-ROW($B$4) -> 15 | C19: =INDIRECT(ADDRESS(ROW()-1,COLUMN())) -> 設計積算機能 | D19: =INDIRECT(ADDRESS(ROW()-1,COLUMN())) -> 基準予算（鑑）画面 | E19: =INDIRECT(ADDRESS(ROW()-1,COLUMN())) -> 予算一覧エリア | F19: =INDIRECT(ADDRESS(ROW()-1,COLUMN())) -> 機器・工事費 | G19: - | H19: - | I19: 書式（形式） | J19: 期待値通りであること（色、フォント、フォントサイズ、文字の寄せ方向、マージン、境界線の太さなど） | K19: 金額は、3桁ずつのカンマ区切り 比率は、小数点以下1桁まで表示されていること | L19: - | M19: OK | O19: 金額：3桁ごとにカンマが打たれることを確認 比率：小数点以下1桁まで表示されることを確認
B20: =ROW()-ROW($B$4) -> 16 | C20: =INDIRECT(ADDRESS(ROW()-1,COLUMN())) -> 設計積算機能 | D20: =INDIRECT(ADDRESS(ROW()-1,COLUMN())) -> 基準予算（鑑）画面 | E20: =INDIRECT(ADDRESS(ROW()-1,COLUMN())) -> 予算一覧エリア | F20: 直接経費他 | G20: - | H20: - | I20: 書式（色） | J20: 期待値通りであること（色、フォント、フォントサイズ、文字の寄せ方向、マージン、境界線の太さなど） | K20: 数値が黒色であること （マイナス値の場合のみ赤色であること） | L20: - | M20: OK | O20: 0以上の値：黒色であることを確認 マイナスの値：赤字であることを確認
B21: =ROW()-ROW($B$4) -> 17 | C21: =INDIRECT(ADDRESS(ROW()-1,COLUMN())) -> 設計積算機能 | D21: =INDIRECT(ADDRESS(ROW()-1,COLUMN())) -> 基準予算（鑑）画面 | E21: =INDIRECT(ADDRESS(ROW()-1,COLUMN())) -> 予算一覧エリア | F21: =INDIRECT(ADDRESS(ROW()-1,COLUMN())) -> 直接経費他 | G21: - | H21: - | I21: 書式（形式） | J21: 期待値通りであること（色、フォント、フォントサイズ、文字の寄せ方向、マージン、境界線の太さなど） | K21: 金額は、3桁ずつのカンマ区切り 比率は、小数点以下1桁まで表示されていること | L21: - | M21: OK | O21: 金額：3桁ごとにカンマが打たれることを確認 比率：小数点以下1桁まで表示されることを確認
B22: =ROW()-ROW($B$4) -> 18 | C22: =INDIRECT(ADDRESS(ROW()-1,COLUMN())) -> 設計積算機能 | D22: =INDIRECT(ADDRESS(ROW()-1,COLUMN())) -> 基準予算（鑑）画面 | E22: =INDIRECT(ADDRESS(ROW()-1,COLUMN())) -> 予算一覧エリア | F22: 直接販売費 | G22: - | H22: - | I22: 書式（色） | J22: 期待値通りであること（色、フォント、フォントサイズ、文字の寄せ方向、マージン、境界線の太さなど） | K22: 数値が黒色であること （マイナス値の場合のみ赤色であること） | L22: - | M22: OK | O22: 0以上の値：黒色であることを確認 マイナスの値：赤字であることを確認
B23: =ROW()-ROW($B$4) -> 19 | C23: =INDIRECT(ADDRESS(ROW()-1,COLUMN())) -> 設計積算機能 | D23: =INDIRECT(ADDRESS(ROW()-1,COLUMN())) -> 基準予算（鑑）画面 | E23: =INDIRECT(ADDRESS(ROW()-1,COLUMN())) -> 予算一覧エリア | F23: =INDIRECT(ADDRESS(ROW()-1,COLUMN())) -> 直接販売費 | G23: - | H23: - | I23: 書式（形式） | J23: 期待値通りであること（色、フォント、フォントサイズ、文字の寄せ方向、マージン、境界線の太さなど） | K23: 金額は、3桁ずつのカンマ区切り 比率は、小数点以下1桁まで表示されていること | L23: - | M23: OK | O23: 金額：3桁ごとにカンマが打たれることを確認 比率：小数点以下1桁まで表示されることを確認
B24: =ROW()-ROW($B$4) -> 20 | C24: =INDIRECT(ADDRESS(ROW()-1,COLUMN())) -> 設計積算機能 | D24: =INDIRECT(ADDRESS(ROW()-1,COLUMN())) -> 基準予算（鑑）画面 | E24: =INDIRECT(ADDRESS(ROW()-1,COLUMN())) -> 予算一覧エリア | F24: B 変動費 計 | G24: - | H24: - | I24: 書式（色） | J24: 期待値通りであること（色、フォント、フォントサイズ、文字の寄せ方向、マージン、境界線の太さなど） | K24: 数値が黒色であること （マイナス値の場合のみ赤色であること） | L24: - | M24: 保留 | N24: 2 | O24: 0以上の値：OK マイナスの値：未確認
B25: =ROW()-ROW($B$4) -> 21 | C25: =INDIRECT(ADDRESS(ROW()-1,COLUMN())) -> 設計積算機能 | D25: =INDIRECT(ADDRESS(ROW()-1,COLUMN())) -> 基準予算（鑑）画面 | E25: =INDIRECT(ADDRESS(ROW()-1,COLUMN())) -> 予算一覧エリア | F25: =INDIRECT(ADDRESS(ROW()-1,COLUMN())) -> B 変動費 計 | G25: - | H25: - | I25: 書式（形式） | J25: 期待値通りであること（色、フォント、フォントサイズ、文字の寄せ方向、マージン、境界線の太さなど） | K25: 金額は、3桁ずつのカンマ区切り 比率は、小数点以下1桁まで表示されていること | L25: - | M25: OK | O25: 金額：3桁ごとにカンマが打たれることを確認 比率：小数点以下1桁まで表示されることを確認
B26: =ROW()-ROW($B$4) -> 22 | C26: =INDIRECT(ADDRESS(ROW()-1,COLUMN())) -> 設計積算機能 | D26: =INDIRECT(ADDRESS(ROW()-1,COLUMN())) -> 基準予算（鑑）画面 | E26: =INDIRECT(ADDRESS(ROW()-1,COLUMN())) -> 予算一覧エリア | F26: =INDIRECT(ADDRESS(ROW()-1,COLUMN())) -> B 変動費 計 | G26: - | H26: - | I26: 初期制御 | J26: 画面を開いた直後の画面で、表示/非表示や活性/非活性が期待値通りであること（権限や状態などによる分岐も確認以下同） | K26: 同じ列の「機器・工事費」「直接経費他」「直接販売費」の合計値であること | L26: - | M26: NG | N26: 5 | O26: NG：基準予算 最新版数の計算で直接販売費の計算式が仕様と異なる（直接販売費が二重計上されている）
B27: =ROW()-ROW($B$4) -> 23 | C27: =INDIRECT(ADDRESS(ROW()-1,COLUMN())) -> 設計積算機能 | D27: =INDIRECT(ADDRESS(ROW()-1,COLUMN())) -> 基準予算（鑑）画面 | E27: =INDIRECT(ADDRESS(ROW()-1,COLUMN())) -> 予算一覧エリア | F27: C 限界利益(A-B) | G27: - | H27: - | I27: 書式（色） | J27: 期待値通りであること（色、フォント、フォントサイズ、文字の寄せ方向、マージン、境界線の太さなど） | K27: 数値が黒色であること （マイナス値の場合のみ赤色であること） | L27: - | M27: 保留 | N27: 2 | O27: 0以上の値：OK マイナスの値：未確認
B28: =ROW()-ROW($B$4) -> 24 | C28: =INDIRECT(ADDRESS(ROW()-1,COLUMN())) -> 設計積算機能 | D28: =INDIRECT(ADDRESS(ROW()-1,COLUMN())) -> 基準予算（鑑）画面 | E28: =INDIRECT(ADDRESS(ROW()-1,COLUMN())) -> 予算一覧エリア | F28: =INDIRECT(ADDRESS(ROW()-1,COLUMN())) -> C 限界利益(A-B) | G28: - | H28: - | I28: 書式（形式） | J28: 期待値通りであること（色、フォント、フォントサイズ、文字の寄せ方向、マージン、境界線の太さなど） | K28: 金額は、3桁ずつのカンマ区切り 比率は、小数点以下1桁まで表示されていること | L28: - | M28: OK | O28: 金額：3桁ごとにカンマが打たれることを確認 比率：小数点以下1桁まで表示されることを確認
B29: =ROW()-ROW($B$4) -> 25 | C29: =INDIRECT(ADDRESS(ROW()-1,COLUMN())) -> 設計積算機能 | D29: =INDIRECT(ADDRESS(ROW()-1,COLUMN())) -> 基準予算（鑑）画面 | E29: =INDIRECT(ADDRESS(ROW()-1,COLUMN())) -> 予算一覧エリア | F29: =INDIRECT(ADDRESS(ROW()-1,COLUMN())) -> C 限界利益(A-B) | G29: - | H29: - | I29: 初期制御 | J29: 画面を開いた直後の画面で、表示/非表示や活性/非活性が期待値通りであること（権限や状態などによる分岐も確認以下同） | K29: 同じ列の「A 工番金額(税抜)」から「B 変動費 計」をマイナスした値であること | L29: - | M29: OK | O29: すべての列で計算式がA-Bになっていることを確認
B30: =ROW()-ROW($B$4) -> 26 | C30: =INDIRECT(ADDRESS(ROW()-1,COLUMN())) -> 設計積算機能 | D30: =INDIRECT(ADDRESS(ROW()-1,COLUMN())) -> 基準予算（鑑）画面 | E30: =INDIRECT(ADDRESS(ROW()-1,COLUMN())) -> 予算一覧エリア | F30: D 設管理費 | G30: - | H30: - | I30: 書式（色） | J30: 期待値通りであること（色、フォント、フォントサイズ、文字の寄せ方向、マージン、境界線の太さなど） | K30: 数値が黒色であること （マイナス値の場合のみ赤色であること） | L30: - | M30: OK | O30: 0以上の値：黒色であることを確認 マイナスの値：赤字であることを確認
B31: =ROW()-ROW($B$4) -> 27 | C31: =INDIRECT(ADDRESS(ROW()-1,COLUMN())) -> 設計積算機能 | D31: =INDIRECT(ADDRESS(ROW()-1,COLUMN())) -> 基準予算（鑑）画面 | E31: =INDIRECT(ADDRESS(ROW()-1,COLUMN())) -> 予算一覧エリア | F31: =INDIRECT(ADDRESS(ROW()-1,COLUMN())) -> D 設管理費 | G31: - | H31: - | I31: 書式（形式） | J31: 期待値通りであること（色、フォント、フォントサイズ、文字の寄せ方向、マージン、境界線の太さなど） | K31: 金額は、3桁ずつのカンマ区切り 比率は、小数点以下1桁まで表示されていること | L31: - | M31: OK | O31: 金額：3桁ごとにカンマが打たれることを確認 比率：小数点以下1桁まで表示されることを確認
B32: =ROW()-ROW($B$4) -> 28 | C32: =INDIRECT(ADDRESS(ROW()-1,COLUMN())) -> 設計積算機能 | D32: =INDIRECT(ADDRESS(ROW()-1,COLUMN())) -> 基準予算（鑑）画面 | E32: =INDIRECT(ADDRESS(ROW()-1,COLUMN())) -> 予算一覧エリア | F32: E 工事利益(C-D) | G32: - | H32: - | I32: 書式（色） | J32: 期待値通りであること（色、フォント、フォントサイズ、文字の寄せ方向、マージン、境界線の太さなど） | K32: 数値が黒色であること （マイナス値の場合のみ赤色であること） | L32: - | M32: 保留 | N32: 2 | O32: 0以上の値：OK マイナスの値：未確認
B33: =ROW()-ROW($B$4) -> 29 | C33: =INDIRECT(ADDRESS(ROW()-1,COLUMN())) -> 設計積算機能 | D33: =INDIRECT(ADDRESS(ROW()-1,COLUMN())) -> 基準予算（鑑）画面 | E33: =INDIRECT(ADDRESS(ROW()-1,COLUMN())) -> 予算一覧エリア | F33: =INDIRECT(ADDRESS(ROW()-1,COLUMN())) -> E 工事利益(C-D) | G33: - | H33: - | I33: 書式（形式） | J33: 期待値通りであること（色、フォント、フォントサイズ、文字の寄せ方向、マージン、境界線の太さなど） | K33: 金額は、3桁ずつのカンマ区切り 比率は、小数点以下1桁まで表示されていること | L33: - | M33: OK | O33: 金額：3桁ごとにカンマが打たれることを確認 比率：小数点以下1桁まで表示されることを確認
B34: =ROW()-ROW($B$4) -> 30 | C34: =INDIRECT(ADDRESS(ROW()-1,COLUMN())) -> 設計積算機能 | D34: =INDIRECT(ADDRESS(ROW()-1,COLUMN())) -> 基準予算（鑑）画面 | E34: =INDIRECT(ADDRESS(ROW()-1,COLUMN())) -> 予算一覧エリア | F34: =INDIRECT(ADDRESS(ROW()-1,COLUMN())) -> E 工事利益(C-D) | G34: - | H34: - | I34: 初期制御 | J34: 画面を開いた直後の画面で、表示/非表示や活性/非活性が期待値通りであること（権限や状態などによる分岐も確認以下同） | K34: 同じ列の「C 限界利益(A-B)」から「D 設管理費」をマイナスした値であること | L34: - | M34: OK | O34: すべての列で計算式がC-Dになっていることを確認
B35: =ROW()-ROW($B$4) -> 31 | C35: =INDIRECT(ADDRESS(ROW()-1,COLUMN())) -> 設計積算機能 | D35: =INDIRECT(ADDRESS(ROW()-1,COLUMN())) -> 基準予算（鑑）画面 | E35: =INDIRECT(ADDRESS(ROW()-1,COLUMN())) -> 予算一覧エリア | F35: F 営業費・本社費 | G35: - | H35: - | I35: 書式（色） | J35: 期待値通りであること（色、フォント、フォントサイズ、文字の寄せ方向、マージン、境界線の太さなど） | K35: 数値が黒色であること （マイナス値の場合のみ赤色であること） | L35: - | M35: OK | O35: 0以上の値：黒色であることを確認 マイナスの値：赤字であることを確認
B36: =ROW()-ROW($B$4) -> 32 | C36: =INDIRECT(ADDRESS(ROW()-1,COLUMN())) -> 設計積算機能 | D36: =INDIRECT(ADDRESS(ROW()-1,COLUMN())) -> 基準予算（鑑）画面 | E36: =INDIRECT(ADDRESS(ROW()-1,COLUMN())) -> 予算一覧エリア | F36: =INDIRECT(ADDRESS(ROW()-1,COLUMN())) -> F 営業費・本社費 | G36: - | H36: - | I36: 書式（形式） | J36: 期待値通りであること（色、フォント、フォントサイズ、文字の寄せ方向、マージン、境界線の太さなど） | K36: 金額は、3桁ずつのカンマ区切り 比率は、小数点以下1桁まで表示されていること | L36: - | M36: OK | O36: 金額：3桁ごとにカンマが打たれることを確認 比率：小数点以下1桁まで表示されることを確認
B37: =ROW()-ROW($B$4) -> 33 | C37: =INDIRECT(ADDRESS(ROW()-1,COLUMN())) -> 設計積算機能 | D37: =INDIRECT(ADDRESS(ROW()-1,COLUMN())) -> 基準予算（鑑）画面 | E37: =INDIRECT(ADDRESS(ROW()-1,COLUMN())) -> 予算一覧エリア | F37: G 営業利益(E-F) | G37: - | H37: - | I37: 書式（色） | J37: 期待値通りであること（色、フォント、フォントサイズ、文字の寄せ方向、マージン、境界線の太さなど） | K37: 数値が黒色であること （マイナス値の場合のみ赤色であること） | L37: - | M37: 保留 | N37: 2 | O37: 0以上の値：OK マイナスの値：未確認
B38: =ROW()-ROW($B$4) -> 34 | C38: =INDIRECT(ADDRESS(ROW()-1,COLUMN())) -> 設計積算機能 | D38: =INDIRECT(ADDRESS(ROW()-1,COLUMN())) -> 基準予算（鑑）画面 | E38: =INDIRECT(ADDRESS(ROW()-1,COLUMN())) -> 予算一覧エリア | F38: =INDIRECT(ADDRESS(ROW()-1,COLUMN())) -> G 営業利益(E-F) | G38: - | H38: - | I38: 書式（形式） | J38: 期待値通りであること（色、フォント、フォントサイズ、文字の寄せ方向、マージン、境界線の太さなど） | K38: 金額は、3桁ずつのカンマ区切り 比率は、小数点以下1桁まで表示されていること | L38: - | M38: OK | O38: 金額：3桁ごとにカンマが打たれることを確認 比率：小数点以下1桁まで表示されることを確認
B39: =ROW()-ROW($B$4) -> 35 | C39: =INDIRECT(ADDRESS(ROW()-1,COLUMN())) -> 設計積算機能 | D39: =INDIRECT(ADDRESS(ROW()-1,COLUMN())) -> 基準予算（鑑）画面 | E39: =INDIRECT(ADDRESS(ROW()-1,COLUMN())) -> 予算一覧エリア | F39: =INDIRECT(ADDRESS(ROW()-1,COLUMN())) -> G 営業利益(E-F) | G39: - | H39: - | I39: 初期制御 | J39: 画面を開いた直後の画面で、表示/非表示や活性/非活性が期待値通りであること（権限や状態などによる分岐も確認以下同） | K39: 同じ列の「E 工事利益(C-D)」から「F 営業費・本社費」をマイナスした値であること | L39: - | M39: OK | O39: すべての列で計算式がE-Fになっていることを確認
B40: =ROW()-ROW($B$4) -> 36 | C40: =INDIRECT(ADDRESS(ROW()-1,COLUMN())) -> 設計積算機能 | D40: =INDIRECT(ADDRESS(ROW()-1,COLUMN())) -> 基準予算（鑑）画面 | E40: ボタンエリア | F40: 登録ボタン | G40: ①アイテム区分はプルダウンから「未選択」を選択する ②版数に「1」を入力する ③設計担当部署コードに「0070」を入力する ④設計担当者コードに「00003」を入力する ⑤積算担当部署コードに「0080」を入力する ⑥積算担当者コードに「00006」を入力する ⑦登録ボタンを押下する | H40: - | I40: 画面反映（エラー有り） | J40: 登録後の自画面反映が正しいこと | K40: ・アイテム区分のテキストボックスの下に 「※アイテム区分を入力してください」というメッセージが表示されること ・「正常に登録しました」というメッセージボックスは表示されないこと | L40: - | M40: NG | N40: 6 | O40: ・NG：「※アイテム区分を入力してください」が表示されない ・NG：「正常に登録しました」が表示される
B41: =ROW()-ROW($B$4) -> 37 | C41: =INDIRECT(ADDRESS(ROW()-1,COLUMN())) -> 設計積算機能 | D41: =INDIRECT(ADDRESS(ROW()-1,COLUMN())) -> 基準予算（鑑）画面 | E41: =INDIRECT(ADDRESS(ROW()-1,COLUMN())) -> ボタンエリア | F41: =INDIRECT(ADDRESS(ROW()-1,COLUMN())) -> 登録ボタン | G41: ①アイテム区分はプルダウンから「全体」を選択する ②版数に「A」を入力する ③設計担当部署コードに「0070」を入力する ④設計担当者コードに「00003」を入力する ⑤積算担当部署コードに「0080」を入力する ⑥積算担当者コードに「00006」を入力する ⑦登録ボタンを押下する | H41: - | I41: 画面反映（エラー有り） | J41: 登録後の自画面反映が正しいこと | K41: ・版数のテキストボックスの下に 「※版数を数値で入力してください」というメッセージが表示されること ・「正常に登録しました」というメッセージボックスは表示されないこと | L41: - | M41: NG | N41: 7 | O41: ・NG：「※版数を数値で入力してください」が表示されない ・NG：「正常に登録しました」が表示される
B42: =ROW()-ROW($B$4) -> 38 | C42: =INDIRECT(ADDRESS(ROW()-1,COLUMN())) -> 設計積算機能 | D42: =INDIRECT(ADDRESS(ROW()-1,COLUMN())) -> 基準予算（鑑）画面 | E42: =INDIRECT(ADDRESS(ROW()-1,COLUMN())) -> ボタンエリア | F42: =INDIRECT(ADDRESS(ROW()-1,COLUMN())) -> 登録ボタン | G42: ①アイテム区分はプルダウンから「全体」を選択する ②版数に「1」を入力する ③設計担当部署コードに「0000」を入力する ④設計担当者コードに「00003」を入力する ⑤積算担当部署コードに「0080」を入力する ⑥積算担当者コードに「00006」を入力する ⑦登録ボタンを押下する | H42: - | I42: 画面反映（エラー有り） | J42: 登録後の自画面反映が正しいこと | K42: ・設計担当部署コードのテキストボックスの右に 「見つかりません」というメッセージが表示されること ・設計担当部署コードのテキストボックスの下に 「※正しい設計担当部署コードを入力してください」というメッセージが表示されること ・「正常に登録しました」というメッセージボックスは表示されないこと | L42: - | M42: NG | N42: 8 | O42: ・OK：設計担当部署コードのテキストボックスの右に「見つかりません」が表示される ・NG：設計担当部署コードのテキストボックスの下に「正しい設計担当部署コードを入力してください」が表示されない ・NG：「正常に登録しました」が表示される
B43: =ROW()-ROW($B$4) -> 39 | C43: =INDIRECT(ADDRESS(ROW()-1,COLUMN())) -> 設計積算機能 | D43: =INDIRECT(ADDRESS(ROW()-1,COLUMN())) -> 基準予算（鑑）画面 | E43: =INDIRECT(ADDRESS(ROW()-1,COLUMN())) -> ボタンエリア | F43: =INDIRECT(ADDRESS(ROW()-1,COLUMN())) -> 登録ボタン | G43: ①アイテム区分はプルダウンから「全体」を選択する ②版数に「1」を入力する ③設計担当部署コードに「0070」を入力する ④設計担当者コードに「00000」を入力する ⑤積算担当部署コードに「0080」を入力する ⑥積算担当者コードに「00006」を入力する ⑦登録ボタンを押下する | H43: - | I43: 画面反映（エラー有り） | J43: 登録後の自画面反映が正しいこと | K43: ・設計担当者コードのテキストボックスの右に 「見つかりません」というメッセージが表示されること ・設計担当者コードのテキストボックスの下に 「※正しい設計担当者コードを入力してください」というメッセージが表示されること ・「正常に登録しました」というメッセージボックスは表示されないこと | L43: - | M43: NG | N43: 9 | O43: ・NG：設計担当者コードのテキストボックスの右に「見つかりません」が表示されない ・NG：設計担当者コードのテキストボックスの下に「正しい設計担当者コードを入力してください」が表示されない ・NG：「正常に登録しました」が表示される
...

Sheet データ定義
A1: データ定義
B3: [データ定義①]
B4: 部署コード | C4: 部署名
B5: 0010 | C5: 管理G
B6: 0020 | C6: 人事G
B7: 0030 | C7: 営業G
B8: 0040 | C8: 品管G
B9: 0050 | C9: 運用G
B10: 0060 | C10: 流通G
B11: 0070 | C11: 設計G
B12: 0080 | C12: 積算G
B13: 0090 | C13: 企画G
B14: 0100 | C14: 広域G
B17: [データ定義②]
B18: 担当者コード | C18: 担当者名
B19: 00001 | C19: しふと たろう
B20: 00002 | C20: しふと はなこ
B21: 00003 | C21: とうきょう たろう
B22: 00004 | C22: とうきょう はなこ
B23: 00005 | C23: さっぽろ たろう
B24: 00006 | C24: さっぽろ はなこ
B25: 00007 | C25: なごや たろう
B26: 00008 | C26: なごや はなこ
B27: 00009 | C27: おおさか たろう
B28: 00010 | C28: おおさか はなこ
B29: 00011 | C29: ふくおか たろう
B30: 00012 | C30: ふくおか はなこ
